<?xml version="1.0" ?>
<mujoco model="planar_manipulator">
    <compiler angle="degree"/>
    <option timestep="0.01" gravity="0 0 -9.81"/>

    <visual>
        <quality shadowsize="2048"/>
        <headlight/>
    </visual>

    <worldbody>
        <light name="main_light" pos="0 0 2" dir="0 0 -1" diffuse="0.8 0.8 0.8"/>
        <body name="base" pos="0 0 0">
            <geom type="box" size="0.1 0.1 0.02" rgba="0.2 0.2 0.8 1"/>
            <joint name="shoulder" type="hinge" axis="0 0 1" range="-90 90"/>
            <body name="link1" pos="0.2 0 0">
                <geom type="capsule" fromto="0 0 0 0.2 0 0" size="0.02" rgba="0.4 0.4 0.4 1"/>
                <joint name="elbow" type="hinge" axis="0 0 1" range="-90 90"/>
                <body name="link2" pos="0.2 0 0">
                    <geom type="capsule" fromto="0 0 0 0.2 0 0" size="0.015" rgba="0.4 0.6 0.4 1"/>
                    <site name="end_effector" pos="0.2 0 0" size="0.01" rgba="1 0 0 1"/>
                </body>
            </body>
        </body>
    </worldbody>

    <actuator>
        <motor name="shoulder" joint="shoulder" ctrlrange="-1 1"/>
        <motor name="elbow" joint="elbow" ctrlrange="-1 1"/>
    </actuator>
</mujoco>
